2025-03-10 15:24:58,751 INFO    MainThread:74709 [wandb_setup.py:_flush():67] Current SDK version is 0.19.8
2025-03-10 15:24:58,751 INFO    MainThread:74709 [wandb_setup.py:_flush():67] Configure stats pid to 74709
2025-03-10 15:24:58,751 INFO    MainThread:74709 [wandb_setup.py:_flush():67] Loading settings from /Users/parasmukati/.config/wandb/settings
2025-03-10 15:24:58,751 INFO    MainThread:74709 [wandb_setup.py:_flush():67] Loading settings from /Users/parasmukati/DA6401/wandb/settings
2025-03-10 15:24:58,751 INFO    MainThread:74709 [wandb_setup.py:_flush():67] Loading settings from environment variables
2025-03-10 15:24:58,752 INFO    MainThread:74709 [wandb_init.py:setup_run_log_directory():647] Logging user logs to /Users/parasmukati/DA6401/wandb/run-20250310_152458-j1a1t45c/logs/debug.log
2025-03-10 15:24:58,752 INFO    MainThread:74709 [wandb_init.py:setup_run_log_directory():648] Logging internal logs to /Users/parasmukati/DA6401/wandb/run-20250310_152458-j1a1t45c/logs/debug-internal.log
2025-03-10 15:24:58,752 INFO    MainThread:74709 [wandb_init.py:init():761] calling init triggers
2025-03-10 15:24:58,752 INFO    MainThread:74709 [wandb_init.py:init():766] wandb.init called with sweep_config: {}
config: {'_wandb': {}}
2025-03-10 15:24:58,752 INFO    MainThread:74709 [wandb_init.py:init():784] starting backend
2025-03-10 15:24:58,752 INFO    MainThread:74709 [wandb_init.py:init():788] sending inform_init request
2025-03-10 15:24:58,798 INFO    MainThread:74709 [backend.py:_multiprocessing_setup():101] multiprocessing start_methods=spawn,fork,forkserver, using: spawn
2025-03-10 15:24:58,799 INFO    MainThread:74709 [wandb_init.py:init():798] backend started and connected
2025-03-10 15:24:58,802 INFO    MainThread:74709 [wandb_init.py:init():891] updated telemetry
2025-03-10 15:24:58,803 INFO    MainThread:74709 [wandb_init.py:init():915] communicating run to backend with 90.0 second timeout
2025-03-10 15:25:01,324 ERROR   MainThread:74709 [wandb_init.py:init():1478] error in wandb.init()
Traceback (most recent call last):
  File "/opt/anaconda3/lib/python3.12/site-packages/wandb/sdk/wandb_init.py", line 1468, in init
    return wi.init(run_settings, run_config)
           ^^^^^^^^^^^^^^^^^^^^^^^^^^^^^^^^^
  File "/opt/anaconda3/lib/python3.12/site-packages/wandb/sdk/wandb_init.py", line 963, in init
    raise error
wandb.errors.errors.CommError: failed to upsert bucket: returned error 404: {"data":{"upsertBucket":null},"errors":[{"message":"entity your_wandb_username not found during upsertBucket","path":["upsertBucket"]}]}
2025-03-10 15:25:02,323 INFO    MsgRouterThr:74709 [mailbox.py:close():129] Closing mailbox, abandoning 0 handles.
